<?xml version="1.0"?>
<robot name="robot">
  <material name="red">
    <color rgba="1 0 0 1"/>
  </material>
  <material name="magenta">
    <color rgba="0.2 0 0.2 1"/>
  </material>
  <material name="green">
    <color rgba="0 1 0 1"/>
  </material>
  <material name="cyan">
    <color rgba="0 1 1 1"/>
  </material>
  <material name="blue">
    <color rgba="0 0 1 1"/>
  </material>
  <material name="orange">
    <color rgba="1 0.5 0 1"/>
  </material>
  <material name="yellow">
    <color rgba="1 1 0 1"/>
  </material>
  <material name="pink">
    <color rgba="1 0 1 1"/>
  </material>
  <material name="grey">
    <color rgba="0.8 0.8 0.8 1"/>
  </material>
  <material name="motor">
    <color rgba="0.2 0.2 0.2 1"/>
  </material>
  <link name="BODY">
    <visual>
      <origin xyz="-0.0 -0.0 -0.23417923317610603" rpy="0 0 0"/>
      <geometry>
        <mesh filename="package://auto_design/urdf/lynel/tmp/BODY_ideal.stl"/>
      </geometry>
      <material name="grey"/>
    </visual>
    <collision>
      <origin xyz="-0.0 -0.0 -0.23417923317610603" rpy="0 0 0"/>
      <geometry>
        <mesh filename="package://auto_design/urdf/lynel/tmp/BODY_ideal.stl"/>
      </geometry>
    </collision>
    <inertial>
      <origin xyz="1.2917096907207977e-05 -0.044790391879004604 0.026629920834307652" rpy="0 0 0"/>
      <mass value="0.36604539999999997"/>
      <inertia ixx="0.005296023704655356" ixy="1.9507736466733212e-06" ixz="-2.5497673378963723e-06" iyy="0.0013814522378742071" iyz="0.001114786787632199" izz="0.004616636187069719"/>
    </inertial>
  </link>
  <link name="FL_UP">
    <visual>
      <origin xyz="-0.04293285941561944 0.1561194887840707 -0.19514936098008837" rpy="0 0 0"/>
      <geometry>
        <mesh filename="package://auto_design/urdf/lynel/tmp/FL_UP_ideal.stl"/>
      </geometry>
      <material name="grey"/>
    </visual>
    <collision>
      <origin xyz="-0.04293285941561944 0.1561194887840707 -0.19514936098008837" rpy="0 0 0"/>
      <geometry>
        <mesh filename="package://auto_design/urdf/lynel/tmp/FL_UP_ideal.stl"/>
      </geometry>
    </collision>
    <inertial>
      <origin xyz="0.0017329554732822341 0.024703077158078207 -0.0061686766537802085" rpy="0 0 0"/>
      <mass value="0.0520102"/>
      <inertia ixx="0.00013104167975420104" ixy="-1.96977598861377e-06" ixz="-1.2580269695463592e-05" iyy="9.53282956009399e-05" iyz="-7.011729912344128e-06" izz="7.27737640122897e-05"/>
    </inertial>
  </link>
  <link name="FL_UP_virtual">
  </link>
  <joint name="FL_UP_joint1" type="revolute">
    <parent link="BODY"/>
    <child link="FL_UP_virtual"/>
    <origin xyz="0.04293285941561944 -0.1561194887840707 -0.039029872196017695" rpy="0 0 0"/>
    <axis xyz="1.0 0.0 0.0"/>
    <limit lower="-1.57" upper="1.57" effort="20" velocity="1.5"/>
  </joint>
  <joint name="FL_UP_joint2" type="revolute">
    <parent link="FL_UP_virtual"/>
    <child link="FL_UP"/>
    <origin xyz="0.0 0.0 0.0" rpy="0 0 0"/>
    <axis xyz="0.0 -1.0 0.0"/>
    <limit lower="-1.57" upper="1.57" effort="20" velocity="1.5"/>
  </joint>
  <link name="FR_UP">
    <visual>
      <origin xyz="0.04293285941561944 0.1561194887840707 -0.19514936098008837" rpy="0 0 0"/>
      <geometry>
        <mesh filename="package://auto_design/urdf/lynel/tmp/FR_UP_ideal.stl"/>
      </geometry>
      <material name="grey"/>
    </visual>
    <collision>
      <origin xyz="0.04293285941561944 0.1561194887840707 -0.19514936098008837" rpy="0 0 0"/>
      <geometry>
        <mesh filename="package://auto_design/urdf/lynel/tmp/FR_UP_ideal.stl"/>
      </geometry>
    </collision>
    <inertial>
      <origin xyz="-0.0011427752466769622 0.024312624472117766 -0.0061905844058599835" rpy="0 0 0"/>
      <mass value="0.052931399999999997"/>
      <inertia ixx="0.00013389862393358202" ixy="1.5254057831646399e-06" ixz="1.3104089531166527e-05" iyy="9.611567465991764e-05" iyz="-6.02866825697037e-06" izz="7.767151423903396e-05"/>
    </inertial>
  </link>
  <link name="FR_UP_virtual">
  </link>
  <joint name="FR_UP_joint1" type="revolute">
    <parent link="BODY"/>
    <child link="FR_UP_virtual"/>
    <origin xyz="-0.04293285941561944 -0.1561194887840707 -0.039029872196017695" rpy="0 0 0"/>
    <axis xyz="-1.0 0.0 0.0"/>
    <limit lower="-1.57" upper="1.57" effort="20" velocity="1.5"/>
  </joint>
  <joint name="FR_UP_joint2" type="revolute">
    <parent link="FR_UP_virtual"/>
    <child link="FR_UP"/>
    <origin xyz="0.0 0.0 0.0" rpy="0 0 0"/>
    <axis xyz="0.0 1.0 0.0"/>
    <limit lower="-1.57" upper="1.57" effort="20" velocity="1.5"/>
  </joint>
  <link name="RR_UP">
    <visual>
      <origin xyz="0.04293285941561944 -0.11708961658805302 -0.21856728429769898" rpy="0 0 0"/>
      <geometry>
        <mesh filename="package://auto_design/urdf/lynel/tmp/RR_UP_ideal.stl"/>
      </geometry>
      <material name="grey"/>
    </visual>
    <collision>
      <origin xyz="0.04293285941561944 -0.11708961658805302 -0.21856728429769898" rpy="0 0 0"/>
      <geometry>
        <mesh filename="package://auto_design/urdf/lynel/tmp/RR_UP_ideal.stl"/>
      </geometry>
    </collision>
    <inertial>
      <origin xyz="-0.0052000577912007726 -0.011596212147078525 -0.007583836796652282" rpy="0 0 0"/>
      <mass value="0.0549336"/>
      <inertia ixx="0.00015444603537303307" ixy="-5.491345691307366e-06" ixz="1.431834926078039e-05" iyy="0.00012652907875855554" iyz="2.4307441180698148e-05" izz="6.020464497347738e-05"/>
    </inertial>
  </link>
  <link name="RR_UP_virtual">
  </link>
  <joint name="RR_UP_joint1" type="revolute">
    <parent link="BODY"/>
    <child link="RR_UP_virtual"/>
    <origin xyz="-0.04293285941561944 0.11708961658805302 -0.015611948878407063" rpy="0 0 0"/>
    <axis xyz="-1.0 0.0 0.0"/>
    <limit lower="-1.57" upper="1.57" effort="20" velocity="1.5"/>
  </joint>
  <joint name="RR_UP_joint2" type="revolute">
    <parent link="RR_UP_virtual"/>
    <child link="RR_UP"/>
    <origin xyz="0.0 0.0 0.0" rpy="0 0 0"/>
    <axis xyz="0.0 -1.0 0.0"/>
    <limit lower="-1.57" upper="1.57" effort="20" velocity="1.5"/>
  </joint>
  <link name="RL_UP">
    <visual>
      <origin xyz="-0.04293285941561944 -0.11708961658805302 -0.21856728429769898" rpy="0 0 0"/>
      <geometry>
        <mesh filename="package://auto_design/urdf/lynel/tmp/RL_UP_ideal.stl"/>
      </geometry>
      <material name="grey"/>
    </visual>
    <collision>
      <origin xyz="-0.04293285941561944 -0.11708961658805302 -0.21856728429769898" rpy="0 0 0"/>
      <geometry>
        <mesh filename="package://auto_design/urdf/lynel/tmp/RL_UP_ideal.stl"/>
      </geometry>
    </collision>
    <inertial>
      <origin xyz="0.005206980497426461 -0.011680058827434434 -0.007559880602264868" rpy="0 0 0"/>
      <mass value="0.0549336"/>
      <inertia ixx="0.00015432540541752233" ixy="5.448825248117678e-06" ixz="-1.426343855920612e-05" iyy="0.0001264483413800484" iyz="2.4348317026009612e-05" izz="6.0109919706536254e-05"/>
    </inertial>
  </link>
  <link name="RL_UP_virtual">
  </link>
  <joint name="RL_UP_joint1" type="revolute">
    <parent link="BODY"/>
    <child link="RL_UP_virtual"/>
    <origin xyz="0.04293285941561944 0.11708961658805302 -0.015611948878407063" rpy="0 0 0"/>
    <axis xyz="1.0 0.0 0.0"/>
    <limit lower="-1.57" upper="1.57" effort="20" velocity="1.5"/>
  </joint>
  <joint name="RL_UP_joint2" type="revolute">
    <parent link="RL_UP_virtual"/>
    <child link="RL_UP"/>
    <origin xyz="0.0 0.0 0.0" rpy="0 0 0"/>
    <axis xyz="0.0 1.0 0.0"/>
    <limit lower="-1.57" upper="1.57" effort="20" velocity="1.5"/>
  </joint>
  <link name="BODY_UP">
    <visual>
      <origin xyz="-0.0 0.1561194887840707 -0.3122389775681414" rpy="0 0 0"/>
      <geometry>
        <mesh filename="package://auto_design/urdf/lynel/tmp/BODY_UP_ideal.stl"/>
      </geometry>
      <material name="grey"/>
    </visual>
    <collision>
      <origin xyz="-0.0 0.1561194887840707 -0.3122389775681414" rpy="0 0 0"/>
      <geometry>
        <mesh filename="package://auto_design/urdf/lynel/tmp/BODY_UP_ideal.stl"/>
      </geometry>
    </collision>
    <inertial>
      <origin xyz="-0.0013382308043315538 0.011473286661758841 0.15366327317340217" rpy="0 0 0"/>
      <mass value="0.200408"/>
      <inertia ixx="0.0010738751456439996" ixy="-1.8129127522277472e-05" ixz="-3.116820486632184e-06" iyy="0.000796659249807232" iyz="-9.772894639235332e-05" izz="0.0006913944635220618"/>
    </inertial>
  </link>
  <joint name="BODY_UP_joint" type="revolute">
    <parent link="BODY"/>
    <child link="BODY_UP"/>
    <origin xyz="0.0 -0.1561194887840707 0.07805974439203535" rpy="0 0 0"/>
    <axis xyz="0.0 0.0 1.0"/>
    <limit lower="-1.57" upper="1.57" effort="20" velocity="1.5"/>
  </joint>
  <link name="FL_LOW">
    <visual>
      <origin xyz="-0.04293285941561944 0.14050753990566361 -0.09757468049004418" rpy="0 0 0"/>
      <geometry>
        <mesh filename="package://auto_design/urdf/lynel/tmp/FL_LOW_ideal.stl"/>
      </geometry>
      <material name="grey"/>
    </visual>
    <collision>
      <origin xyz="-0.04293285941561944 0.14050753990566361 -0.09757468049004418" rpy="0 0 0"/>
      <geometry>
        <mesh filename="package://auto_design/urdf/lynel/tmp/FL_LOW_ideal.stl"/>
      </geometry>
    </collision>
    <inertial>
      <origin xyz="-0.004604781257910334 -0.013405355363665133 -0.06971715736192424" rpy="0 0 0"/>
      <mass value="0.009306"/>
      <inertia ixx="5.546638535353541e-06" ixy="-7.570513131313088e-08" ixz="-1.2025733333333357e-07" iyy="4.113694702020211e-06" iyz="-1.386727166666665e-06" izz="4.188076237373726e-06"/>
    </inertial>
  </link>
  <joint name="FL_LOW_joint" type="revolute">
    <parent link="FL_UP"/>
    <child link="FL_LOW"/>
    <origin xyz="0.0 0.01561194887840708 -0.09757468049004418" rpy="0 0 0"/>
    <axis xyz="1.0 0.0 0.0"/>
    <limit lower="-1.57" upper="1.57" effort="20" velocity="1.5"/>
  </joint>
  <link name="FR_LOW">
    <visual>
      <origin xyz="0.04293285941561944 0.14050753990566361 -0.09757468049004418" rpy="0 0 0"/>
      <geometry>
        <mesh filename="package://auto_design/urdf/lynel/tmp/FR_LOW_ideal.stl"/>
      </geometry>
      <material name="grey"/>
    </visual>
    <collision>
      <origin xyz="0.04293285941561944 0.14050753990566361 -0.09757468049004418" rpy="0 0 0"/>
      <geometry>
        <mesh filename="package://auto_design/urdf/lynel/tmp/FR_LOW_ideal.stl"/>
      </geometry>
    </collision>
    <inertial>
      <origin xyz="0.004685514669592404 -0.013542783865551494 -0.06972016941011701" rpy="0 0 0"/>
      <mass value="0.0093624"/>
      <inertia ixx="5.5291418172690665e-06" ixy="5.9364161646586216e-08" ixz="1.0482722389558255e-07" iyy="4.112822299196785e-06" iyz="-1.3436566214859462e-06" izz="4.194432419678722e-06"/>
    </inertial>
  </link>
  <joint name="FR_LOW_joint" type="revolute">
    <parent link="FR_UP"/>
    <child link="FR_LOW"/>
    <origin xyz="0.0 0.01561194887840708 -0.09757468049004418" rpy="0 0 0"/>
    <axis xyz="-1.0 0.0 0.0"/>
    <limit lower="-1.57" upper="1.57" effort="20" velocity="1.5"/>
  </joint>
  <link name="RR_LOW">
    <visual>
      <origin xyz="0.04293285941561944 -0.14050753990566361 -0.11708961658805302" rpy="0 0 0"/>
      <geometry>
        <mesh filename="package://auto_design/urdf/lynel/tmp/RR_LOW_ideal.stl"/>
      </geometry>
      <material name="grey"/>
    </visual>
    <collision>
      <origin xyz="0.04293285941561944 -0.14050753990566361 -0.11708961658805302" rpy="0 0 0"/>
      <geometry>
        <mesh filename="package://auto_design/urdf/lynel/tmp/RR_LOW_ideal.stl"/>
      </geometry>
    </collision>
    <inertial>
      <origin xyz="0.0021793858598750035 -0.01995568202856951 -0.08561979408877532" rpy="0 0 0"/>
      <mass value="0.0107254"/>
      <inertia ixx="7.531368562664329e-06" ixy="-6.865748466257673e-08" ixz="-1.056490797546125e-08" iyy="6.1323408588957106e-06" iyz="-1.8004618711656477e-06" izz="4.697406967572328e-06"/>
    </inertial>
  </link>
  <joint name="RR_LOW_joint" type="revolute">
    <parent link="RR_UP"/>
    <child link="RR_LOW"/>
    <origin xyz="0.0 0.023417923317610594 -0.10147766770964596" rpy="0 0 0"/>
    <axis xyz="-1.0 0.0 0.0"/>
    <limit lower="-1.57" upper="1.57" effort="20" velocity="1.5"/>
  </joint>
  <link name="RL_LOW">
    <visual>
      <origin xyz="-0.04293285941561944 -0.14050753990566361 -0.11708961658805302" rpy="0 0 0"/>
      <geometry>
        <mesh filename="package://auto_design/urdf/lynel/tmp/RL_LOW_ideal.stl"/>
      </geometry>
      <material name="grey"/>
    </visual>
    <collision>
      <origin xyz="-0.04293285941561944 -0.14050753990566361 -0.11708961658805302" rpy="0 0 0"/>
      <geometry>
        <mesh filename="package://auto_design/urdf/lynel/tmp/RL_LOW_ideal.stl"/>
      </geometry>
    </collision>
    <inertial>
      <origin xyz="-0.002244796995301168 -0.019606819190810393 -0.08450581144954372" rpy="0 0 0"/>
      <mass value="0.011101399999999999"/>
      <inertia ixx="7.93439155800167e-06" ixy="8.863599068586016e-08" ixz="1.0472344199830617e-07" iyy="6.501096909398815e-06" iyz="-1.9031999322608e-06" izz="4.869940220152419e-06"/>
    </inertial>
  </link>
  <joint name="RL_LOW_joint" type="revolute">
    <parent link="RL_UP"/>
    <child link="RL_LOW"/>
    <origin xyz="0.0 0.023417923317610594 -0.10147766770964596" rpy="0 0 0"/>
    <axis xyz="1.0 0.0 0.0"/>
    <limit lower="-1.57" upper="1.57" effort="20" velocity="1.5"/>
  </joint>
  <link name="L_ARM">
    <visual>
      <origin xyz="-0.10147766770964595 0.1561194887840707 -0.4293285941561944" rpy="0 0 0"/>
      <geometry>
        <mesh filename="package://auto_design/urdf/lynel/tmp/L_ARM_ideal.stl"/>
      </geometry>
      <material name="grey"/>
    </visual>
    <collision>
      <origin xyz="-0.10147766770964595 0.1561194887840707 -0.4293285941561944" rpy="0 0 0"/>
      <geometry>
        <mesh filename="package://auto_design/urdf/lynel/tmp/L_ARM_ideal.stl"/>
      </geometry>
    </collision>
    <inertial>
      <origin xyz="0.0013193651008584217 -0.0017649118475341896 -0.045394387748487086" rpy="0 0 0"/>
      <mass value="0.09172519999999999"/>
      <inertia ixx="0.0005748711806533125" ixy="2.7237210298217422e-05" ixz="9.117338857194121e-05" iyy="0.0005811812422125388" iyz="-0.00012393172246566954" izz="0.0001773157630267493"/>
    </inertial>
  </link>
  <joint name="L_ARM_joint" type="revolute">
    <parent link="BODY_UP"/>
    <child link="L_ARM"/>
    <origin xyz="0.10147766770964595 0.0 0.117089616588053" rpy="0 0 0"/>
    <axis xyz="1.0 0.0 0.0"/>
    <limit lower="-1.57" upper="1.57" effort="20" velocity="1.5"/>
  </joint>
  <link name="R_ARM">
    <visual>
      <origin xyz="0.10147766770964595 0.1561194887840707 -0.4293285941561944" rpy="0 0 0"/>
      <geometry>
        <mesh filename="package://auto_design/urdf/lynel/tmp/R_ARM_ideal.stl"/>
      </geometry>
      <material name="grey"/>
    </visual>
    <collision>
      <origin xyz="0.10147766770964595 0.1561194887840707 -0.4293285941561944" rpy="0 0 0"/>
      <geometry>
        <mesh filename="package://auto_design/urdf/lynel/tmp/R_ARM_ideal.stl"/>
      </geometry>
    </collision>
    <inertial>
      <origin xyz="-0.0065275726251517036 -0.0008630648823618192 -0.04270244774115872" rpy="0 0 0"/>
      <mass value="0.0945546"/>
      <inertia ixx="0.0005772254545670574" ixy="-6.0368085619842705e-06" ixz="-7.400828112486425e-05" iyy="0.00059356119845015" iyz="-0.00010986682274778819" izz="0.000221942857343676"/>
    </inertial>
  </link>
  <joint name="R_ARM_joint" type="revolute">
    <parent link="BODY_UP"/>
    <child link="R_ARM"/>
    <origin xyz="-0.10147766770964595 0.0 0.117089616588053" rpy="0 0 0"/>
    <axis xyz="-1.0 0.0 0.0"/>
    <limit lower="-1.57" upper="1.57" effort="20" velocity="1.5"/>
  </joint>
<gazebo>
   <plugin filename="libgazebo_ros_p3d.so" name="p3d_base_controller">
   <alwaysOn>true</alwaysOn>
       <updateRate>10.0</updateRate>
       <bodyName>base_link</bodyName>
       <topicName>odom/ground_truth</topicName>
       <gaussianNoise>0.00000001</gaussianNoise>
       <frameName>world</frameName>
       <xyzOffsets>0 0 0</xyzOffsets>
       <rpyOffsets>0 0 0</rpyOffsets>
   </plugin>
</gazebo>
<gazebo>
   <plugin filename="libgazebo_ros_control.so" name="gazebo_ros_control">
       <legacyModeNS>true</legacyModeNS>
   </plugin>
</gazebo>
</robot>
