<?xml version="1.0"?>
<robot name="robot">
  <material name="red">
    <color rgba="1 0 0 1"/>
  </material>
  <material name="magenta">
    <color rgba="0.2 0 0.2 1"/>
  </material>
  <material name="green">
    <color rgba="0 1 0 1"/>
  </material>
  <material name="cyan">
    <color rgba="0 1 1 1"/>
  </material>
  <material name="blue">
    <color rgba="0 0 1 1"/>
  </material>
  <material name="orange">
    <color rgba="1 0.5 0 1"/>
  </material>
  <material name="yellow">
    <color rgba="1 1 0 1"/>
  </material>
  <material name="pink">
    <color rgba="1 0 1 1"/>
  </material>
  <material name="grey">
    <color rgba="0.8 0.8 0.8 1"/>
  </material>
  <material name="motor">
    <color rgba="0.2 0.2 0.2 1"/>
  </material>
  <link name="BODY">
    <visual>
      <origin xyz="0 0 0" rpy="0 0 0"/>
      <geometry>
        <mesh filename="package://auto_design/urdf/lynel/tmp/BODY.stl"/>
      </geometry>
      <material name="grey"/>
    </visual>
    <collision>
      <origin xyz="0 0 0" rpy="0 0 0"/>
      <geometry>
        <mesh filename="package://auto_design/urdf/lynel/tmp/BODY.stl"/>
      </geometry>
    </collision>
    <inertial>
      <origin xyz="-0.00021115500436141963 -0.013487929561110688 0.2543296449536168" rpy="0 0 0"/>
      <mass value="4.046"/>
      <inertia ixx="0.06060960439372222" ixy="-0.0009474648546712994" ixz="0.0006160156124567555" iyy="0.014589246203657704" iyz="0.013177204884824528" izz="0.05293520625926955"/>
    </inertial>
  </link>
  <link name="FL_UP">
    <visual>
      <origin xyz="-0.03434651991735905 0.1461194887840707 -0.2050321663270944" rpy="0 0 0"/>
      <geometry>
        <mesh filename="package://auto_design/urdf/lynel/tmp/FL_UP.stl"/>
      </geometry>
      <material name="grey"/>
    </visual>
    <collision>
      <origin xyz="-0.03434651991735905 0.1461194887840707 -0.2050321663270944" rpy="0 0 0"/>
      <geometry>
        <mesh filename="package://auto_design/urdf/lynel/tmp/FL_UP.stl"/>
      </geometry>
    </collision>
    <inertial>
      <origin xyz="0.05763335708890861 0.06693947698643765 -0.015087039478404257" rpy="0 0 0"/>
      <mass value="0.799"/>
      <inertia ixx="0.0019399036045056502" ixy="1.0649123904881099e-05" ixz="-0.0002827025969962482" iyy="0.001363106678347928" iyz="-7.65537196495623e-05" izz="0.001172411944931159"/>
    </inertial>
  </link>
  <link name="FL_UP_virtual">
  </link>
  <joint name="FL_UP_joint1" type="revolute">
    <parent link="BODY"/>
    <child link="FL_UP_virtual"/>
    <origin xyz="-0.015653480082640954 -0.1961194887840707 0.2050321663270944" rpy="0 0 0"/>
    <axis xyz="0.0 -1.0 0.0"/>
    <limit lower="-1.57" upper="1.57" effort="20" velocity="1.5"/>
  </joint>
  <joint name="FL_UP_joint2" type="revolute">
    <parent link="FL_UP_virtual"/>
    <child link="FL_UP"/>
    <origin xyz="0.05 0.05 0.0" rpy="0 0 0"/>
    <axis xyz="1.0 0.0 0.0"/>
    <limit lower="-1.57" upper="1.57" effort="20" velocity="1.5"/>
  </joint>
  <link name="FR_UP">
    <visual>
      <origin xyz="0.04114747212391462 0.1461194887840707 -0.22042495153126945" rpy="0 0 0"/>
      <geometry>
        <mesh filename="package://auto_design/urdf/lynel/tmp/FR_UP.stl"/>
      </geometry>
      <material name="grey"/>
    </visual>
    <collision>
      <origin xyz="0.04114747212391462 0.1461194887840707 -0.22042495153126945" rpy="0 0 0"/>
      <geometry>
        <mesh filename="package://auto_design/urdf/lynel/tmp/FR_UP.stl"/>
      </geometry>
    </collision>
    <inertial>
      <origin xyz="-0.04988639698220549 -0.03246312456307385 -0.03706288295358312" rpy="0 0 0"/>
      <mass value="0.8576"/>
      <inertia ixx="0.0020550565240205223" ixy="-4.508720848880592e-05" ixz="0.0002718977413712693" iyy="0.0015111314528918121" iyz="-0.0001096340974813437" izz="0.0011657575314832122"/>
    </inertial>
  </link>
  <link name="FR_UP_virtual">
  </link>
  <joint name="FR_UP_joint1" type="revolute">
    <parent link="BODY"/>
    <child link="FR_UP_virtual"/>
    <origin xyz="0.008852527876085379 -0.0961194887840707 0.22042495153126945" rpy="0 0 0"/>
    <axis xyz="0.0 1.0 0.0"/>
    <limit lower="-1.57" upper="1.57" effort="20" velocity="1.5"/>
  </joint>
  <joint name="FR_UP_joint2" type="revolute">
    <parent link="FR_UP_virtual"/>
    <child link="FR_UP"/>
    <origin xyz="-0.05 -0.05 0.0" rpy="0 0 0"/>
    <axis xyz="-1.0 0.0 0.0"/>
    <limit lower="-1.57" upper="1.57" effort="20" velocity="1.5"/>
  </joint>
  <link name="RR_UP">
    <visual>
      <origin xyz="0.032918210083995196 -0.11873949756223358 -0.21537922350297276" rpy="0 0 0"/>
      <geometry>
        <mesh filename="package://auto_design/urdf/lynel/tmp/RR_UP.stl"/>
      </geometry>
      <material name="grey"/>
    </visual>
    <collision>
      <origin xyz="0.032918210083995196 -0.11873949756223358 -0.21537922350297276" rpy="0 0 0"/>
      <geometry>
        <mesh filename="package://auto_design/urdf/lynel/tmp/RR_UP.stl"/>
      </geometry>
    </collision>
    <inertial>
      <origin xyz="-0.060440644864018817 0.037757236913929446 -0.007504083909438741" rpy="0 0 0"/>
      <mass value="1.1228"/>
      <inertia ixx="0.003966581987887413" ixy="-0.00030583507303170727" ixz="0.0008276515853224012" iyy="0.003421685226220139" iyz="0.0007965851033131448" izz="0.0016535358995368597"/>
    </inertial>
  </link>
  <link name="RR_UP_virtual">
  </link>
  <joint name="RR_UP_joint1" type="revolute">
    <parent link="BODY"/>
    <child link="RR_UP_virtual"/>
    <origin xyz="0.0170817899160048 0.06873949756223358 0.21537922350297276" rpy="0 0 0"/>
    <axis xyz="0.0 -1.0 0.0"/>
    <limit lower="-1.57" upper="1.57" effort="20" velocity="1.5"/>
  </joint>
  <joint name="RR_UP_joint2" type="revolute">
    <parent link="RR_UP_virtual"/>
    <child link="RR_UP"/>
    <origin xyz="-0.05 0.05 0.0" rpy="0 0 0"/>
    <axis xyz="-1.0 0.0 0.0"/>
    <limit lower="-1.57" upper="1.57" effort="20" velocity="1.5"/>
  </joint>
  <link name="RL_UP">
    <visual>
      <origin xyz="-0.04425679276116055 -0.127089616588053 -0.21499467854783633" rpy="0 0 0"/>
      <geometry>
        <mesh filename="package://auto_design/urdf/lynel/tmp/RL_UP.stl"/>
      </geometry>
      <material name="grey"/>
    </visual>
    <collision>
      <origin xyz="-0.04425679276116055 -0.127089616588053 -0.21499467854783633" rpy="0 0 0"/>
      <geometry>
        <mesh filename="package://auto_design/urdf/lynel/tmp/RL_UP.stl"/>
      </geometry>
    </collision>
    <inertial>
      <origin xyz="0.05316771273740524 -0.07013300863354913 -0.004089525136571709" rpy="0 0 0"/>
      <mass value="0.9962000000000001"/>
      <inertia ixx="0.0035110067476410607" ixy="0.00024164356655289958" ixz="-0.0005439308361774732" iyy="0.0029817901525798197" iyz="0.0007105058562537592" izz="0.0012688038305561427"/>
    </inertial>
  </link>
  <link name="RL_UP_virtual">
  </link>
  <joint name="RL_UP_joint1" type="revolute">
    <parent link="BODY"/>
    <child link="RL_UP_virtual"/>
    <origin xyz="-0.005743207238839449 0.177089616588053 0.21499467854783633" rpy="0 0 0"/>
    <axis xyz="0.0 1.0 0.0"/>
    <limit lower="-1.57" upper="1.57" effort="20" velocity="1.5"/>
  </joint>
  <joint name="RL_UP_joint2" type="revolute">
    <parent link="RL_UP_virtual"/>
    <child link="RL_UP"/>
    <origin xyz="0.05 -0.04999999999999998 0.0" rpy="0 0 0"/>
    <axis xyz="1.0 0.0 0.0"/>
    <limit lower="-1.57" upper="1.57" effort="20" velocity="1.5"/>
  </joint>
  <link name="BODY_UP">
    <visual>
      <origin xyz="-0.008095586888848195 0.1592562769181121 -0.30694873768533604" rpy="0 0 0"/>
      <geometry>
        <mesh filename="package://auto_design/urdf/lynel/tmp/BODY_UP.stl"/>
      </geometry>
      <material name="grey"/>
    </visual>
    <collision>
      <origin xyz="-0.008095586888848195 0.1592562769181121 -0.30694873768533604" rpy="0 0 0"/>
      <geometry>
        <mesh filename="package://auto_design/urdf/lynel/tmp/BODY_UP.stl"/>
      </geometry>
    </collision>
    <inertial>
      <origin xyz="-0.006874025766949557 0.01117041148781428 0.1495783715521874" rpy="0 0 0"/>
      <mass value="5.1306"/>
      <inertia ixx="0.02960174992086722" ixy="-0.0001649287054145659" ixz="0.0005248376145090567" iyy="0.02633023251159682" iyz="-0.0031550319179043467" izz="0.0184589411055242"/>
    </inertial>
  </link>
  <joint name="BODY_UP_joint" type="revolute">
    <parent link="BODY"/>
    <child link="BODY_UP"/>
    <origin xyz="0.008095586888848195 -0.1592562769181121 0.30694873768533604" rpy="0 0 0"/>
    <axis xyz="0.0 0.0 1.0"/>
    <limit lower="-1.57" upper="1.57" effort="20" velocity="1.5"/>
  </joint>
  <link name="FL_LOW">
    <visual>
      <origin xyz="-0.04252450929659363 0.14137368163794709 -0.0925884142384419" rpy="0 0 0"/>
      <geometry>
        <mesh filename="package://auto_design/urdf/lynel/tmp/FL_LOW.stl"/>
      </geometry>
      <material name="grey"/>
    </visual>
    <collision>
      <origin xyz="-0.04252450929659363 0.14137368163794709 -0.0925884142384419" rpy="0 0 0"/>
      <geometry>
        <mesh filename="package://auto_design/urdf/lynel/tmp/FL_LOW.stl"/>
      </geometry>
    </collision>
    <inertial>
      <origin xyz="0.005662905267563682 -0.008201709367439497 -0.0339497974826164" rpy="0 0 0"/>
      <mass value="0.3926"/>
      <inertia ixx="0.000684293973509934" ixy="-3.3321388181355104e-05" ixz="-0.00013238819154355518" iyy="0.0006285855119714741" iyz="-8.303511462047894e-05" izz="0.00027379354559347994"/>
    </inertial>
  </link>
  <joint name="FL_LOW_joint" type="revolute">
    <parent link="FL_UP"/>
    <child link="FL_LOW"/>
    <origin xyz="0.008177989379234578 0.004745807146123617 -0.11244375208865248" rpy="0 0 0"/>
    <axis xyz="1.0 0.0 0.0"/>
    <limit lower="-1.57" upper="1.57" effort="20" velocity="1.5"/>
  </joint>
  <link name="FR_LOW">
    <visual>
      <origin xyz="0.045304219972294044 0.13902978857806794 -0.09111249407729925" rpy="0 0 0"/>
      <geometry>
        <mesh filename="package://auto_design/urdf/lynel/tmp/FR_LOW.stl"/>
      </geometry>
      <material name="grey"/>
    </visual>
    <collision>
      <origin xyz="0.045304219972294044 0.13902978857806794 -0.09111249407729925" rpy="0 0 0"/>
      <geometry>
        <mesh filename="package://auto_design/urdf/lynel/tmp/FR_LOW.stl"/>
      </geometry>
    </collision>
    <inertial>
      <origin xyz="-0.003518902262991598 -0.009879646857595237 -0.04229311169567911" rpy="0 0 0"/>
      <mass value="0.31980000000000003"/>
      <inertia ixx="0.00046743306441525986" ixy="3.328800813008127e-05" ixz="0.00012416878048780437" iyy="0.0004319835897435908" iyz="-8.510053470919346e-05" izz="0.0002327447592245155"/>
    </inertial>
  </link>
  <joint name="FR_LOW_joint" type="revolute">
    <parent link="FR_UP"/>
    <child link="FR_LOW"/>
    <origin xyz="-0.004156747848379423 0.00708970020600276 -0.12931245745397021" rpy="0 0 0"/>
    <axis xyz="-1.0 0.0 0.0"/>
    <limit lower="-1.57" upper="1.57" effort="20" velocity="1.5"/>
  </joint>
  <link name="RR_LOW">
    <visual>
      <origin xyz="0.025952452896666863 -0.13823140000454662 -0.12264720677300084" rpy="0 0 0"/>
      <geometry>
        <mesh filename="package://auto_design/urdf/lynel/tmp/RR_LOW.stl"/>
      </geometry>
      <material name="grey"/>
    </visual>
    <collision>
      <origin xyz="0.025952452896666863 -0.13823140000454662 -0.12264720677300084" rpy="0 0 0"/>
      <geometry>
        <mesh filename="package://auto_design/urdf/lynel/tmp/RR_LOW.stl"/>
      </geometry>
    </collision>
    <inertial>
      <origin xyz="-0.017556042805717462 -0.011095097639602924 -0.06499615896806449" rpy="0 0 0"/>
      <mass value="0.3264"/>
      <inertia ixx="0.0007814186274509784" ixy="9.003235294117632e-06" ixz="5.954411764705891e-05" iyy="0.0006892217524509785" iyz="-0.00016763411764705876" izz="0.00018129959558823558"/>
    </inertial>
  </link>
  <joint name="RR_LOW_joint" type="revolute">
    <parent link="RR_UP"/>
    <child link="RR_LOW"/>
    <origin xyz="0.006965757187328334 0.019491902442313035 -0.09273201672997193" rpy="0 0 0"/>
    <axis xyz="-1.0 0.0 0.0"/>
    <limit lower="-1.57" upper="1.57" effort="20" velocity="1.5"/>
  </joint>
  <link name="RL_LOW">
    <visual>
      <origin xyz="-0.0412060694504116 -0.13960477484431955 -0.09891162720881845" rpy="0 0 0"/>
      <geometry>
        <mesh filename="package://auto_design/urdf/lynel/tmp/RL_LOW.stl"/>
      </geometry>
      <material name="grey"/>
    </visual>
    <collision>
      <origin xyz="-0.0412060694504116 -0.13960477484431955 -0.09891162720881845" rpy="0 0 0"/>
      <geometry>
        <mesh filename="package://auto_design/urdf/lynel/tmp/RL_LOW.stl"/>
      </geometry>
    </collision>
    <inertial>
      <origin xyz="0.004886790327199644 -0.011255701252093298 -0.040358658271016895" rpy="0 0 0"/>
      <mass value="0.40540000000000004"/>
      <inertia ixx="0.0007405472471632933" ixy="-2.2971933892451887e-05" ixz="-9.501059694129239e-05" iyy="0.0006506006068080893" iyz="-0.00014733730389738544" izz="0.00028001423778983717"/>
    </inertial>
  </link>
  <joint name="RL_LOW_joint" type="revolute">
    <parent link="RL_UP"/>
    <child link="RL_LOW"/>
    <origin xyz="-0.003050723310748946 0.012515158256266527 -0.11608305133901788" rpy="0 0 0"/>
    <axis xyz="1.0 0.0 0.0"/>
    <limit lower="-1.57" upper="1.57" effort="20" velocity="1.5"/>
  </joint>
  <link name="L_ARM">
    <visual>
      <origin xyz="-0.10295175670433557 0.16379390738872185 -0.4393285941561944" rpy="0 0 0"/>
      <geometry>
        <mesh filename="package://auto_design/urdf/lynel/tmp/L_ARM.stl"/>
      </geometry>
      <material name="grey"/>
    </visual>
    <collision>
      <origin xyz="-0.10295175670433557 0.16379390738872185 -0.4393285941561944" rpy="0 0 0"/>
      <geometry>
        <mesh filename="package://auto_design/urdf/lynel/tmp/L_ARM.stl"/>
      </geometry>
    </collision>
    <inertial>
      <origin xyz="0.006216505800031816 0.006441435981171223 -0.061878457360810046" rpy="0 0 0"/>
      <mass value="1.5696"/>
      <inertia ixx="0.009806210080912413" ixy="0.0006469408129459523" ixz="0.0016478811060142676" iyy="0.009703609918450666" iyz="-0.0026173013098878856" izz="0.003285942955530019"/>
    </inertial>
  </link>
  <joint name="L_ARM_joint" type="revolute">
    <parent link="BODY_UP"/>
    <child link="L_ARM"/>
    <origin xyz="0.09485616981548738 -0.004537630470609777 0.13237985647085837" rpy="0 0 0"/>
    <axis xyz="1.0 0.0 0.0"/>
    <limit lower="-1.57" upper="1.57" effort="20" velocity="1.5"/>
  </joint>
  <link name="R_ARM">
    <visual>
      <origin xyz="0.09147766770964594 0.16084206706643656 -0.4354098979467089" rpy="0 0 0"/>
      <geometry>
        <mesh filename="package://auto_design/urdf/lynel/tmp/R_ARM.stl"/>
      </geometry>
      <material name="grey"/>
    </visual>
    <collision>
      <origin xyz="0.09147766770964594 0.16084206706643656 -0.4354098979467089" rpy="0 0 0"/>
      <geometry>
        <mesh filename="package://auto_design/urdf/lynel/tmp/R_ARM.stl"/>
      </geometry>
    </collision>
    <inertial>
      <origin xyz="-0.024565332420465782 0.00797079027474798 -0.05082479502932996" rpy="0 0 0"/>
      <mass value="1.5864"/>
      <inertia ixx="0.008445255562279418" ixy="-0.0004347706580937982" ixz="-0.0016285785325264744" iyy="0.00884118360753899" iyz="-0.0018567760564800878" izz="0.0033633225787947463"/>
    </inertial>
  </link>
  <joint name="R_ARM_joint" type="revolute">
    <parent link="BODY_UP"/>
    <child link="R_ARM"/>
    <origin xyz="-0.09957325459849414 -0.0015857901483244774 0.1284611602613729" rpy="0 0 0"/>
    <axis xyz="-1.0 0.0 0.0"/>
    <limit lower="-1.57" upper="1.57" effort="20" velocity="1.5"/>
  </joint>
<gazebo>
   <plugin filename="libgazebo_ros_p3d.so" name="p3d_base_controller">
   <alwaysOn>true</alwaysOn>
       <updateRate>10.0</updateRate>
       <bodyName>base_link</bodyName>
       <topicName>odom/ground_truth</topicName>
       <gaussianNoise>0.00000001</gaussianNoise>
       <frameName>world</frameName>
       <xyzOffsets>0 0 0</xyzOffsets>
       <rpyOffsets>0 0 0</rpyOffsets>
   </plugin>
</gazebo>
<gazebo>
   <plugin filename="libgazebo_ros_control.so" name="gazebo_ros_control">
       <legacyModeNS>true</legacyModeNS>
   </plugin>
</gazebo>
</robot>
